============================= test session starts =============================
platform win32 -- Python 3.12.10, pytest-8.4.2, pluggy-1.6.0
django: version: 5.2.6, settings: server.settings (from ini)
Using --randomly-seed=3331248215
rootdir: E:\progetti\pareri
configfile: setup.cfg
plugins: anyio-4.10.0, django-test-migrations-1.5.0, hypothesis-6.138.16, cov-7.0.0, django-4.11.1, randomly-4.0.1, timeout-2.4.0
timeout: 5.0s
timeout method: thread
timeout func_only: False
collected 96 items

tests\test_server\test_admin.py .............F......F................... [ 41%]
.                                                                        [ 42%]
tests\test_server\test_urls.py ..                                        [ 44%]
tests\test_common_base_model.py .......                                  [ 52%]
tests\test_apps\test_accounts\test_additional_models_forms.py .......... [ 62%]
.............                                                            [ 76%]
tests\test_apps\test_main\test_models\test_blog_post_model.py .          [ 77%]
tests\test_apps\test_accounts\test_models_case.py .                      [ 78%]
tests\test_apps\test_accounts\test_more_models_forms.py ....             [ 82%]
tests\test_apps\test_accounts\test_admin_and_apps.py ..                  [ 84%]
tests\test_apps\test_main\test_models\test_migrations\test_blog_post_migrations.py . [ 85%]
                                                                         [ 85%]
tests\test_apps\test_accounts\test_migrations.py .                       [ 86%]
tests\test_server\test_admin.py ....                                     [ 90%]
tests\test_server\test_urls.py ...                                       [ 93%]
tests\test_misc\test_length_is.py ...                                    [ 96%]
tests\test_apps\test_main\test_views\test_index_view.py .                [ 97%]
tests\test_server\test_logging.py .                                      [ 98%]
tests\test_misc\test_project_integration.py .
ERROR: Coverage failure: total of 99 is less than fail-under=100
                                                                         [100%]

================================== FAILURES ===================================
_____________________ test_custom_admin_dummy_model_smoke _____________________
.venv\Lib\site-packages\django\db\backends\utils.py:105: in _execute
    return self.cursor.execute(sql, params)
           ^^^^^^^^^^^^^^^^^^^^^^^^^^^^^^^^
E   psycopg2.errors.UndefinedTable: ERRORE:  la relazione "main_dummymodel" non esiste
E   LINE 1: INSERT INTO "main_dummymodel" ("name") VALUES ('test') RETUR...
E                       ^

The above exception was the direct cause of the following exception:
tests\test_server\test_admin.py:5: in test_custom_admin_dummy_model_smoke
    obj = DummyModel.objects.create(name="test")
          ^^^^^^^^^^^^^^^^^^^^^^^^^^^^^^^^^^^^^^
.venv\Lib\site-packages\django\db\models\manager.py:87: in manager_method
    return getattr(self.get_queryset(), name)(*args, **kwargs)
           ^^^^^^^^^^^^^^^^^^^^^^^^^^^^^^^^^^^^^^^^^^^^^^^^^^^
.venv\Lib\site-packages\django\db\models\query.py:663: in create
    obj.save(force_insert=True, using=self.db)
.venv\Lib\site-packages\django\db\models\base.py:902: in save
    self.save_base(
.venv\Lib\site-packages\django\db\models\base.py:1008: in save_base
    updated = self._save_table(
.venv\Lib\site-packages\django\db\models\base.py:1169: in _save_table
    results = self._do_insert(
.venv\Lib\site-packages\django\db\models\base.py:1210: in _do_insert
    return manager._insert(
.venv\Lib\site-packages\django\db\models\manager.py:87: in manager_method
    return getattr(self.get_queryset(), name)(*args, **kwargs)
           ^^^^^^^^^^^^^^^^^^^^^^^^^^^^^^^^^^^^^^^^^^^^^^^^^^^
.venv\Lib\site-packages\django\db\models\query.py:1868: in _insert
    return query.get_compiler(using=using).execute_sql(returning_fields)
           ^^^^^^^^^^^^^^^^^^^^^^^^^^^^^^^^^^^^^^^^^^^^^^^^^^^^^^^^^^^^^
.venv\Lib\site-packages\django\db\models\sql\compiler.py:1882: in execute_sql
    cursor.execute(sql, params)
.venv\Lib\site-packages\django\db\backends\utils.py:79: in execute
    return self._execute_with_wrappers(
.venv\Lib\site-packages\django\db\backends\utils.py:92: in _execute_with_wrappers
    return executor(sql, params, many, context)
           ^^^^^^^^^^^^^^^^^^^^^^^^^^^^^^^^^^^^
.venv\Lib\site-packages\django\db\backends\utils.py:100: in _execute
    with self.db.wrap_database_errors:
         ^^^^^^^^^^^^^^^^^^^^^^^^^^^^
.venv\Lib\site-packages\django\db\utils.py:91: in __exit__
    raise dj_exc_value.with_traceback(traceback) from exc_value
.venv\Lib\site-packages\django\db\backends\utils.py:105: in _execute
    return self.cursor.execute(sql, params)
           ^^^^^^^^^^^^^^^^^^^^^^^^^^^^^^^^
E   django.db.utils.ProgrammingError: ERRORE:  la relazione "main_dummymodel" non esiste
E   LINE 1: INSERT INTO "main_dummymodel" ("name") VALUES ('test') RETUR...
E                       ^
__________________ test_admin_changelist[site12-DummyModel] ___________________
.venv\Lib\site-packages\django\db\backends\utils.py:105: in _execute
    return self.cursor.execute(sql, params)
           ^^^^^^^^^^^^^^^^^^^^^^^^^^^^^^^^
E   psycopg2.errors.UndefinedTable: ERRORE:  la relazione "main_dummymodel" non esiste
E   LINE 1: SELECT COUNT(*) AS "__count" FROM "main_dummymodel"
E                                             ^

The above exception was the direct cause of the following exception:
tests\test_server\test_admin.py:84: in test_admin_changelist
    response = admin_client.get(url, {'q': 'something'})
               ^^^^^^^^^^^^^^^^^^^^^^^^^^^^^^^^^^^^^^^^^
.venv\Lib\site-packages\django\test\client.py:1124: in get
    response = super().get(
.venv\Lib\site-packages\django\test\client.py:475: in get
    return self.generic(
.venv\Lib\site-packages\django\test\client.py:671: in generic
    return self.request(**r)
           ^^^^^^^^^^^^^^^^^
.venv\Lib\site-packages\django\test\client.py:1087: in request
    self.check_exception(response)
.venv\Lib\site-packages\django\test\client.py:802: in check_exception
    raise exc_value
.venv\Lib\site-packages\django\core\handlers\exception.py:55: in inner
    response = get_response(request)
               ^^^^^^^^^^^^^^^^^^^^^
.venv\Lib\site-packages\django\core\handlers\base.py:197: in _get_response
    response = wrapped_callback(request, *callback_args, **callback_kwargs)
               ^^^^^^^^^^^^^^^^^^^^^^^^^^^^^^^^^^^^^^^^^^^^^^^^^^^^^^^^^^^^
.venv\Lib\site-packages\django\contrib\admin\options.py:719: in wrapper
    return self.admin_site.admin_view(view)(*args, **kwargs)
           ^^^^^^^^^^^^^^^^^^^^^^^^^^^^^^^^^^^^^^^^^^^^^^^^^
.venv\Lib\site-packages\django\utils\decorators.py:192: in _view_wrapper
    result = _process_exception(request, e)
             ^^^^^^^^^^^^^^^^^^^^^^^^^^^^^^
.venv\Lib\site-packages\django\utils\decorators.py:190: in _view_wrapper
    response = view_func(request, *args, **kwargs)
               ^^^^^^^^^^^^^^^^^^^^^^^^^^^^^^^^^^^
.venv\Lib\site-packages\django\views\decorators\cache.py:80: in _view_wrapper
    response = view_func(request, *args, **kwargs)
               ^^^^^^^^^^^^^^^^^^^^^^^^^^^^^^^^^^^
.venv\Lib\site-packages\django\contrib\admin\sites.py:246: in inner
    return view(request, *args, **kwargs)
           ^^^^^^^^^^^^^^^^^^^^^^^^^^^^^^
.venv\Lib\site-packages\django\utils\decorators.py:48: in _wrapper
    return bound_method(*args, **kwargs)
           ^^^^^^^^^^^^^^^^^^^^^^^^^^^^^
.venv\Lib\site-packages\django\utils\decorators.py:192: in _view_wrapper
    result = _process_exception(request, e)
             ^^^^^^^^^^^^^^^^^^^^^^^^^^^^^^
.venv\Lib\site-packages\django\utils\decorators.py:190: in _view_wrapper
    response = view_func(request, *args, **kwargs)
               ^^^^^^^^^^^^^^^^^^^^^^^^^^^^^^^^^^^
.venv\Lib\site-packages\django\contrib\admin\options.py:2024: in changelist_view
    cl = self.get_changelist_instance(request)
         ^^^^^^^^^^^^^^^^^^^^^^^^^^^^^^^^^^^^^
.venv\Lib\site-packages\django\contrib\admin\options.py:867: in get_changelist_instance
    return ChangeList(
.venv\Lib\site-packages\django\contrib\admin\views\main.py:146: in __init__
    self.get_results(request)
.venv\Lib\site-packages\django\contrib\admin\views\main.py:313: in get_results
    result_count = paginator.count
                   ^^^^^^^^^^^^^^^
.venv\Lib\site-packages\django\utils\functional.py:47: in __get__
    res = instance.__dict__[self.name] = self.func(instance)
                                         ^^^^^^^^^^^^^^^^^^^
.venv\Lib\site-packages\django\core\paginator.py:110: in count
    return c()
           ^^^
.venv\Lib\site-packages\django\db\models\query.py:604: in count
    return self.query.get_count(using=self.db)
           ^^^^^^^^^^^^^^^^^^^^^^^^^^^^^^^^^^^
.venv\Lib\site-packages\django\db\models\sql\query.py:644: in get_count
    return obj.get_aggregation(using, {"__count": Count("*")})["__count"]
           ^^^^^^^^^^^^^^^^^^^^^^^^^^^^^^^^^^^^^^^^^^^^^^^^^^^
.venv\Lib\site-packages\django\db\models\sql\query.py:626: in get_aggregation
    result = compiler.execute_sql(SINGLE)
             ^^^^^^^^^^^^^^^^^^^^^^^^^^^^
.venv\Lib\site-packages\django\db\models\sql\compiler.py:1623: in execute_sql
    cursor.execute(sql, params)
.venv\Lib\site-packages\debug_toolbar\panels\sql\tracking.py:234: in execute
    return self._record(super().execute, sql, params)
           ^^^^^^^^^^^^^^^^^^^^^^^^^^^^^^^^^^^^^^^^^^
.venv\Lib\site-packages\debug_toolbar\panels\sql\tracking.py:160: in _record
    return method(sql, params)
           ^^^^^^^^^^^^^^^^^^^
.venv\Lib\site-packages\django\db\backends\utils.py:79: in execute
    return self._execute_with_wrappers(
.venv\Lib\site-packages\django\db\backends\utils.py:92: in _execute_with_wrappers
    return executor(sql, params, many, context)
           ^^^^^^^^^^^^^^^^^^^^^^^^^^^^^^^^^^^^
.venv\Lib\site-packages\query_counter\decorators.py:82: in __call__
    execute(sql, params, many, context)
.venv\Lib\site-packages\django\db\backends\utils.py:100: in _execute
    with self.db.wrap_database_errors:
         ^^^^^^^^^^^^^^^^^^^^^^^^^^^^
.venv\Lib\site-packages\django\db\utils.py:91: in __exit__
    raise dj_exc_value.with_traceback(traceback) from exc_value
.venv\Lib\site-packages\django\db\backends\utils.py:105: in _execute
    return self.cursor.execute(sql, params)
           ^^^^^^^^^^^^^^^^^^^^^^^^^^^^^^^^
E   django.db.utils.ProgrammingError: ERRORE:  la relazione "main_dummymodel" non esiste
E   LINE 1: SELECT COUNT(*) AS "__count" FROM "main_dummymodel"
E                                             ^
---------------------------- Captured stdout call -----------------------------
[32m+--------+--------+--------+--------+------------+-------+----------+
| Select | Insert | Update | Delete | Duplicates | Total | Duration |
+--------+--------+--------+--------+------------+-------+----------+
|   0    |   0    |   0    |   0    |     0      |   0   |   0.03   |
+--------+--------+--------+--------+------------+-------+----------+[0m
Target: /pareri/main/dummymodel/ django.contrib.admin.options.changelist_view
---------------------------- Captured stderr call -----------------------------
timestamp='2025-10-15T14:21:03.768459Z' level='error' event='Internal Server Error: /pareri/main/dummymodel/' logger='django.request' exc_info=(<class 'django.db.utils.ProgrammingError'>, ProgrammingError('ERRORE:  la relazione "main_dummymodel" non esiste\nLINE 1: SELECT COUNT(*) AS "__count" FROM "main_dummymodel"\n                                          ^\n'), <traceback object at 0x0000027E95F15440>)
------------------------------ Captured log call ------------------------------
ERROR    django.request:log.py:253 Internal Server Error: /pareri/main/dummymodel/
Traceback (most recent call last):
  File "E:\progetti\pareri\.venv\Lib\site-packages\django\db\backends\utils.py", line 105, in _execute
    return self.cursor.execute(sql, params)
           ^^^^^^^^^^^^^^^^^^^^^^^^^^^^^^^^
psycopg2.errors.UndefinedTable: ERRORE:  la relazione "main_dummymodel" non esiste
LINE 1: SELECT COUNT(*) AS "__count" FROM "main_dummymodel"
                                          ^


The above exception was the direct cause of the following exception:

Traceback (most recent call last):
  File "E:\progetti\pareri\.venv\Lib\site-packages\django\core\handlers\exception.py", line 55, in inner
    response = get_response(request)
               ^^^^^^^^^^^^^^^^^^^^^
  File "E:\progetti\pareri\.venv\Lib\site-packages\django\core\handlers\base.py", line 197, in _get_response
    response = wrapped_callback(request, *callback_args, **callback_kwargs)
               ^^^^^^^^^^^^^^^^^^^^^^^^^^^^^^^^^^^^^^^^^^^^^^^^^^^^^^^^^^^^
  File "E:\progetti\pareri\.venv\Lib\site-packages\django\contrib\admin\options.py", line 719, in wrapper
    return self.admin_site.admin_view(view)(*args, **kwargs)
           ^^^^^^^^^^^^^^^^^^^^^^^^^^^^^^^^^^^^^^^^^^^^^^^^^
  File "E:\progetti\pareri\.venv\Lib\site-packages\django\utils\decorators.py", line 192, in _view_wrapper
    result = _process_exception(request, e)
             ^^^^^^^^^^^^^^^^^^^^^^^^^^^^^^
  File "E:\progetti\pareri\.venv\Lib\site-packages\django\utils\decorators.py", line 190, in _view_wrapper
    response = view_func(request, *args, **kwargs)
               ^^^^^^^^^^^^^^^^^^^^^^^^^^^^^^^^^^^
  File "E:\progetti\pareri\.venv\Lib\site-packages\django\views\decorators\cache.py", line 80, in _view_wrapper
    response = view_func(request, *args, **kwargs)
               ^^^^^^^^^^^^^^^^^^^^^^^^^^^^^^^^^^^
  File "E:\progetti\pareri\.venv\Lib\site-packages\django\contrib\admin\sites.py", line 246, in inner
    return view(request, *args, **kwargs)
           ^^^^^^^^^^^^^^^^^^^^^^^^^^^^^^
  File "E:\progetti\pareri\.venv\Lib\site-packages\django\utils\decorators.py", line 48, in _wrapper
    return bound_method(*args, **kwargs)
           ^^^^^^^^^^^^^^^^^^^^^^^^^^^^^
  File "E:\progetti\pareri\.venv\Lib\site-packages\django\utils\decorators.py", line 192, in _view_wrapper
    result = _process_exception(request, e)
             ^^^^^^^^^^^^^^^^^^^^^^^^^^^^^^
  File "E:\progetti\pareri\.venv\Lib\site-packages\django\utils\decorators.py", line 190, in _view_wrapper
    response = view_func(request, *args, **kwargs)
               ^^^^^^^^^^^^^^^^^^^^^^^^^^^^^^^^^^^
  File "E:\progetti\pareri\.venv\Lib\site-packages\django\contrib\admin\options.py", line 2024, in changelist_view
    cl = self.get_changelist_instance(request)
         ^^^^^^^^^^^^^^^^^^^^^^^^^^^^^^^^^^^^^
  File "E:\progetti\pareri\.venv\Lib\site-packages\django\contrib\admin\options.py", line 867, in get_changelist_instance
    return ChangeList(
           ^^^^^^^^^^^
  File "E:\progetti\pareri\.venv\Lib\site-packages\django\contrib\admin\views\main.py", line 146, in __init__
    self.get_results(request)
  File "E:\progetti\pareri\.venv\Lib\site-packages\django\contrib\admin\views\main.py", line 313, in get_results
    result_count = paginator.count
                   ^^^^^^^^^^^^^^^
  File "E:\progetti\pareri\.venv\Lib\site-packages\django\utils\functional.py", line 47, in __get__
    res = instance.__dict__[self.name] = self.func(instance)
                                         ^^^^^^^^^^^^^^^^^^^
  File "E:\progetti\pareri\.venv\Lib\site-packages\django\core\paginator.py", line 110, in count
    return c()
           ^^^
  File "E:\progetti\pareri\.venv\Lib\site-packages\django\db\models\query.py", line 604, in count
    return self.query.get_count(using=self.db)
           ^^^^^^^^^^^^^^^^^^^^^^^^^^^^^^^^^^^
  File "E:\progetti\pareri\.venv\Lib\site-packages\django\db\models\sql\query.py", line 644, in get_count
    return obj.get_aggregation(using, {"__count": Count("*")})["__count"]
           ^^^^^^^^^^^^^^^^^^^^^^^^^^^^^^^^^^^^^^^^^^^^^^^^^^^
  File "E:\progetti\pareri\.venv\Lib\site-packages\django\db\models\sql\query.py", line 626, in get_aggregation
    result = compiler.execute_sql(SINGLE)
             ^^^^^^^^^^^^^^^^^^^^^^^^^^^^
  File "E:\progetti\pareri\.venv\Lib\site-packages\django\db\models\sql\compiler.py", line 1623, in execute_sql
    cursor.execute(sql, params)
  File "E:\progetti\pareri\.venv\Lib\site-packages\debug_toolbar\panels\sql\tracking.py", line 234, in execute
    return self._record(super().execute, sql, params)
           ^^^^^^^^^^^^^^^^^^^^^^^^^^^^^^^^^^^^^^^^^^
  File "E:\progetti\pareri\.venv\Lib\site-packages\debug_toolbar\panels\sql\tracking.py", line 160, in _record
    return method(sql, params)
           ^^^^^^^^^^^^^^^^^^^
  File "E:\progetti\pareri\.venv\Lib\site-packages\django\db\backends\utils.py", line 79, in execute
    return self._execute_with_wrappers(
           ^^^^^^^^^^^^^^^^^^^^^^^^^^^^
  File "E:\progetti\pareri\.venv\Lib\site-packages\django\db\backends\utils.py", line 92, in _execute_with_wrappers
    return executor(sql, params, many, context)
           ^^^^^^^^^^^^^^^^^^^^^^^^^^^^^^^^^^^^
  File "E:\progetti\pareri\.venv\Lib\site-packages\query_counter\decorators.py", line 82, in __call__
    execute(sql, params, many, context)
  File "E:\progetti\pareri\.venv\Lib\site-packages\django\db\backends\utils.py", line 100, in _execute
    with self.db.wrap_database_errors:
         ^^^^^^^^^^^^^^^^^^^^^^^^^^^^
  File "E:\progetti\pareri\.venv\Lib\site-packages\django\db\utils.py", line 91, in __exit__
    raise dj_exc_value.with_traceback(traceback) from exc_value
  File "E:\progetti\pareri\.venv\Lib\site-packages\django\db\backends\utils.py", line 105, in _execute
    return self.cursor.execute(sql, params)
           ^^^^^^^^^^^^^^^^^^^^^^^^^^^^^^^^
django.db.utils.ProgrammingError: ERRORE:  la relazione "main_dummymodel" non esiste
LINE 1: SELECT COUNT(*) AS "__count" FROM "main_dummymodel"
                                          ^
=============================== tests coverage ================================
______________ coverage: platform win32, python 3.12.10-final-0 _______________

Name                                          Stmts   Miss Branch BrPart  Cover   Missing
-----------------------------------------------------------------------------------------
server\admin.py                                  50      0      6      1    98%   61->65
server\apps\main\models.py                       20      1      0      0    95%   46
server\settings\environments\development.py      32      0      2      1    97%   41->46
tests\test_server\test_admin.py                 176     10      0      0    94%   7-17, 289
-----------------------------------------------------------------------------------------
TOTAL                                          1012     11     54      2    99%

49 files skipped due to complete coverage.
Coverage HTML written to dir htmlcov
Coverage XML written to file coverage.xml
FAIL Required test coverage of 100% not reached. Total coverage: 98.78%
=========================== short test summary info ===========================
FAILED tests/test_server/test_admin.py::test_custom_admin_dummy_model_smoke
FAILED tests/test_server/test_admin.py::test_admin_changelist[site12-DummyModel]
======================== 2 failed, 94 passed in 28.47s ========================
